Workbook

Sheet README
A1: Oracle Corporation (ORCL) — independent forecast & valuation model
A5: Prepared for | B5: Joshua Lacroix
A6: Prepared by | B6: Independent build (Claude Code). Not investment advice.
A7: Model date | B7: 2026-08-28
A8: Market data as of | B8: 2026-08-27 close. ORCL $151.94.
A10: PRIMARY SOURCES
A11: FY2026 Form 10-K | B11: SEC EDGAR CIK 0001341439, accession 0001193125-26-277521, filed 2026-06-22, FYE 2026-05-31
A12: Q4/FY26 press release | B12: Exhibit 99.1 to Form 8-K filed 2026-06-10, accession 0001193125-26-265848
A13: Market / comps data | B13: stockanalysis.com, pulled 2026-08-27/28 (single source, single date)
A14: Risk-free rate | B14: 10-year US Treasury (^TNX) 4.672%, 2026-08-27
A16: WHAT IS *NOT* SOURCED HERE
A17: Q4 FY26 slide deck / call transcript | B17: investor.oracle.com returned HTTP 403. Any figure originating only from the call (FY27 net capex ~$70bn, "no additional debt in calendar 2026", component cost pass-through) is flagged UNVERIFIED SECONDARY and is NOT used as a model input.
A18: FY2028+ consensus | B18: Paywalled at source. FY28 estimates in this model are the analyst's own, not consensus.
A20: COLOUR LEGEND
A21: Blue text | B21: Hardcoded input / scenario lever — edit these
A22: Black text | B22: Formula calculated on this sheet
A23: Green text | B23: Link to another sheet in this workbook
A24: Yellow fill | B24: Key assumption. The answer is most sensitive to these.
A26: HOW TO DRIVE THE MODEL
A27: 1. | B27: Set the scenario on Inputs!B4 to Base, Bull or Bear. Everything downstream re-solves.
A28: 2. | B28: Edit any blue cell in the BASE / BULL / BEAR blocks on the Inputs tab. Never edit a black cell.
A29: 3. | B29: Every driver row carries a source note in column J of the Inputs tab.
A31: TAB MAP
A32: Inputs | B32: All drivers, three scenarios, with source notes
A33: Historicals | B33: FY2024–FY2026 actuals, every line tied to the 10-K
A34: RPO_Schedule | B34: The disclosed 12% / 34% / 34% / 20% conversion schedule and the revenue build off it
A35: Capex_Depreciation | B35: Capex→CIP→in-service→depreciation vintage waterfall. The most important mechanical tab.
A36: Income_Statement | B36: FY24A–FY31E, GAAP
A37: NonGAAP_Recon | B37: Full GAAP↔non-GAAP bridge including the tax-rate wedge
A38: Cash_Flow | B38: OCF, capex (three definitions), FCF
A39: Debt_Shares | B39: Debt schedule, interest, share count, ATM, mandatory convertible
A40: Valuation_RPO_NPV | B40: PRIMARY valuation: contract-level NPV of the $638bn backlog
A41: Valuation_DCF | B41: Cross-check: unlevered FCF DCF and FCFE
A42: Sensitivity | B42: Two-way tables and driver ranking
A43: ROIC_Breakeven | B43: Required OCI gross margin to clear WACC. The central question.
... A46: Formula_Audit | B46: Every simplification, circularity break and known limitation

Sheet Inputs
A1: INPUTS — every driver, three scenarios
A2: Blue = editable. Column J carries the source or the basis for the estimate. E = analyst estimate, D = disclosed by Oracle.
A4: SCENARIO | B4: Base | C4: <- type Base, Bull or Bear
A5: scenario index | B5: =MATCH($B$4,$A$996:$A$998,0)
A7: Driver | B7: ACTIVE (single) | C7: FY2027 | D7: FY2028 | E7: FY2029 | F7: FY2030 | G7: FY2031 | J7: Source / basis (D = disclosed by Oracle, E = analyst estimate)
A8: — RPO CONVERSION —
A9: RPO at 5/31/2026 ($m) | B9: =CHOOSE($B$5,B201,B321,B441) | J9: D: 10-K Note 1 & MD&A. $638bn vs $137.8bn at 5/31/25.
A10: Disclosed: recognised over next 12 months | B10: =CHOOSE($B$5,B202,B322,B442) | J10: D: 10-K Note 1 verbatim.
A11: Disclosed: months 13–36 | B11: =CHOOSE($B$5,B203,B323,B443) | J11: D: 10-K Note 1 verbatim.
A12: Disclosed: months 37–60 | B12: =CHOOSE($B$5,B204,B324,B444) | J12: D: 10-K Note 1 verbatim.
A13: Disclosed: thereafter (residual) | B13: =CHOOSE($B$5,B205,B325,B445) | J13: D: "and the remainder thereafter".
A14: "Legacy" (pre-AI) backlog ($m) | B14: =CHOOSE($B$5,B206,B326,B446) | J14: E: ≈ the 5/31/25 RPO of $137.8bn. Splits the backlog into fast-converting legacy and slow-converting AI.
A15: AI backlog never recognised (counterparty) | B15: =CHOOSE($B$5,B207,B327,B447) | J15: E: KEY LEVER. 10-K discloses NO customer >10% of revenue and does not quantify RPO concentration.
A16: Legacy backlog conversion, % per year | C16: =CHOOSE($B$5,C208,C328,C448) | D16: =CHOOSE($B$5,D208,D328,D448) | E16: =CHOOSE($B$5,E208,E328,E448) | F16: =CHOOSE($B$5,F208,F328,F448) | G16: =CHOOSE($B$5,G208,G328,G448) | J16: E: pre-AI RPO converted ~60–62% in 12 months when last tagged (FY2021 10-K).
A17: Share of the m13–36 bucket falling in FY28 | B17: =CHOOSE($B$5,B209,B329,B449) | J17: E: intra-bucket timing. Oracle discloses the 24-month total only.
A18: Share of the m37–60 bucket falling in FY30 | B18: =CHOOSE($B$5,B210,B330,B450) | J18: E: intra-bucket timing.
A19: New bookings signed after 5/31/26 ($m) | C19: =CHOOSE($B$5,C211,C331,C451) | D19: =CHOOSE($B$5,D211,D331,D451) | E19: =CHOOSE($B$5,E211,E331,E451) | F19: =CHOOSE($B$5,F211,F331,F451) | G19: =CHOOSE($B$5,G211,G331,G451) | J19: E: PURE ESTIMATE. Dominates FY30–31. Oracle added ~$500bn of RPO in FY26 alone; not repeatable.
A20: New-bookings conversion, % per year | C20: =CHOOSE($B$5,C212,C332,C452) | D20: =CHOOSE($B$5,D212,D332,D452) | E20: =CHOOSE($B$5,E212,E332,E452) | F20: =CHOOSE($B$5,F212,F332,F452) | G20: =CHOOSE($B$5,G212,G332,G452) | J20: E: assumes new contracts convert on a similar back-loaded profile to the AI backlog.
A21: Revenue not covered by RPO, FY27 ($m) | B21: =CHOOSE($B$5,B213,B333,B453) | J21: E: hardware, non-committed consumption, some services/new licence.
A22: growth | B22: =CHOOSE($B$5,B214,B334,B454) | J22: E.
A23: — SEGMENT DRIVERS (IaaS is the residual) —
A24: Cloud Applications (SaaS) growth | C24: =CHOOSE($B$5,C216,C336,C456) | D24: =CHOOSE($B$5,D216,D336,D456) | E24: =CHOOSE($B$5,E216,E336,E456) | F24: =CHOOSE($B$5,F216,F336,F456) | G24: =CHOOSE($B$5,G216,G336,G456) | J24: E: FY26A +11.3%. Mgmt guides Oracle Health to double-digit growth in FY27 (PR 6/10/26).
A25: Software licence growth | C25: =CHOOSE($B$5,C217,C337,C457) | D25: =CHOOSE($B$5,D217,D337,D457) | E25: =CHOOSE($B$5,E217,E337,E457) | F25: =CHOOSE($B$5,F217,F337,F457) | G25: =CHOOSE($B$5,G217,G337,G457) | J25: E: FY24–26A $5,081→$5,201→$4,737m, structurally declining.
A26: Software support growth | C26: =CHOOSE($B$5,C218,C338,C458) | D26: =CHOOSE($B$5,D218,D338,D458) | E26: =CHOOSE($B$5,E218,E338,E458) | F26: =CHOOSE($B$5,F218,F338,F458) | G26: =CHOOSE($B$5,G218,G338,G458) | J26: E: FY24–26A $19,609→$19,523→$19,804m. A genuine annuity.
A27: Services growth | C27: =CHOOSE($B$5,C219,C339,C459) | D27: =CHOOSE($B$5,D219,D339,D459) | E27: =CHOOSE($B$5,E219,E339,E459) | F27: =CHOOSE($B$5,F219,F339,F459) | G27: =CHOOSE($B$5,G219,G339,G459) | J27: E: FY26A +9.7%.
A28: Hardware growth | C28: =CHOOSE($B$5,C220,C340,C460) | D28: =CHOOSE($B$5,D220,D340,D460) | E28: =CHOOSE($B$5,E220,E340,E460) | F28: =CHOOSE($B$5,F220,F340,F460) | G28: =CHOOSE($B$5,G220,G340,G460) | J28: E: FY26A +5.0%.
A29: — MARGINS —
A30: IaaS cost ex-depreciation, % of IaaS revenue | C30: =CHOOSE($B$5,C222,C342,C462) | D30: =CHOOSE($B$5,D222,D342,D462) | E30: =CHOOSE($B$5,E222,E342,E462) | F30: =CHOOSE($B$5,F222,F342,F462) | G30: =CHOOSE($B$5,G222,G342,G462) | J30: E: KEY LEVER. Power, bandwidth, site labour, component pass-through. Oracle does not disclose OCI cost structure.
A31: Share of total depreciation charged to IaaS COGS | C31: =CHOOSE($B$5,C223,C343,C463) | D31: =CHOOSE($B$5,D223,D343,D463) | E31: =CHOOSE($B$5,E223,E343,E463) | F31: =CHOOSE($B$5,F223,F343,F463) | G31: =CHOOSE($B$5,G223,G343,G463) | J31: E: not disclosed. Depreciation is inside cost of revenue as Oracle reports it.
A32: SaaS gross margin | C32: =CHOOSE($B$5,C224,C344,C464) | D32: =CHOOSE($B$5,D224,D344,D464) | E32: =CHOOSE($B$5,E224,E344,E464) | F32: =CHOOSE($B$5,F224,F344,F464) | G32: =CHOOSE($B$5,G224,G344,G464) | J32: E: not disclosed separately.
A33: Software support gross margin | C33: =CHOOSE($B$5,C225,C345,C465) | D33: =CHOOSE($B$5,D225,D345,D465) | E33: =CHOOSE($B$5,E225,E345,E465) | F33: =CHOOSE($B$5,F225,F345,F465) | G33: =CHOOSE($B$5,G225,G345,G465) | J33: E: not disclosed separately.
A34: Software licence gross margin | C34: =CHOOSE($B$5,C226,C346,C466) | D34: =CHOOSE($B$5,D226,D346,D466) | E34: =CHOOSE($B$5,E226,E346,E466) | F34: =CHOOSE($B$5,F226,F346,F466) | G34: =CHOOSE($B$5,G226,G346,G466) | J34: E: not disclosed separately.
A35: Services gross margin | C35: =CHOOSE($B$5,C227,C347,C467) | D35: =CHOOSE($B$5,D227,D347,D467) | E35: =CHOOSE($B$5,E227,E347,E467) | F35: =CHOOSE($B$5,F227,F347,F467) | G35: =CHOOSE($B$5,G227,G347,G467) | J35: D: FY26A 20.7% ($5,743m rev / $4,556m cost, 10-K R4).
A36: Hardware gross margin | C36: =CHOOSE($B$5,C228,C348,C468) | D36: =CHOOSE($B$5,D228,D348,D468) | E36: =CHOOSE($B$5,E228,E348,E468) | F36: =CHOOSE($B$5,F228,F348,F468) | G36: =CHOOSE($B$5,G228,G348,G468) | J36: D: FY26A 71.9% ($3,084m / $868m, 10-K R4).
A37: — OPERATING EXPENSE —
A38: Sales & marketing, % of revenue | C38: =CHOOSE($B$5,C230,C350,C470) | D38: =CHOOSE($B$5,D230,D350,D470) | E38: =CHOOSE($B$5,E230,E350,E470) | F38: =CHOOSE($B$5,F230,F350,F470) | G38: =CHOOSE($B$5,G230,G350,G470) | J38: E: FY26A 12.4%. Scale leverage as revenue steps up.
A39: R&D growth | C39: =CHOOSE($B$5,C231,C351,C471) | D39: =CHOOSE($B$5,D231,D351,D471) | E39: =CHOOSE($B$5,E231,E351,E471) | F39: =CHOOSE($B$5,F231,F351,F471) | G39: =CHOOSE($B$5,G231,G351,G471) | J39: E: FY26A $10,272m, +4.2%. 43,000 of 141,000 employees are in R&D (10-K Item 1).
A40: G&A growth | C40: =CHOOSE($B$5,C232,C352,C472) | D40: =CHOOSE($B$5,D232,D352,D472) | E40: =CHOOSE($B$5,E232,E352,E472) | F40: =CHOOSE($B$5,F232,F352,F472) | G40: =CHOOSE($B$5,G232,G352,G472) | J40: E.
A41: Stock-based compensation growth | C41: =CHOOSE($B$5,C233,C353,C473) | D41: =CHOOSE($B$5,D233,D353,D473) | E41: =CHOOSE($B$5,E233,E353,E473) | F41: =CHOOSE($B$5,F233,F353,F473) | G41: =CHOOSE($B$5,G233,G353,G473) | J41: E: FY26A $4,811m. 10-K MD&A: annualised net dilution 1.0%/yr since 6/1/2023.
A42: Restructuring & other ($m) | C42: =CHOOSE($B$5,C234,C354,C474) | D42: =CHOOSE($B$5,D234,D354,D474) | E42: =CHOOSE($B$5,E234,E354,E474) | F42: =CHOOSE($B$5,F234,F354,F474) | G42: =CHOOSE($B$5,G234,G354,G474) | J42: E: FY26A $1,838m (headcount 154k→141k). 10-K R59.
...

Sheet Historicals
A1: HISTORICALS — FY2024 / FY2025 / FY2026 actuals
A2: Every line ties to the FY2026 Form 10-K (acc 0001193125-26-277521) or the Q4 FY26 press release (Ex-99.1 to the 8-K of 2026-06-10).
A4: $ millions | B4: FY2024A | C4: FY2025A | D4: FY2026A | J4: Source
A5: Cloud revenue | B5: 19774 | C5: 24506 | D5: 33989 | J5: 10-K Consolidated Statements of Operations (R4)
A6: Cloud infrastructure (IaaS) | B6: 6840 | C6: 10234 | D6: 18101 | J6: 10-K Note 14, revenue by offering (R89)
A7: Cloud applications (SaaS) | B7: 12934 | C7: 14272 | D7: 15888 | J7: 10-K Note 14 (R89)
A8: Software revenue | B8: 24690 | C8: 24724 | D8: 24541 | J8: 10-K R4
A9: Software licence | B9: 5081 | C9: 5201 | D9: 4737 | J9: 10-K Note 14 (R89)
A10: Software support | B10: 19609 | C10: 19523 | D10: 19804 | J10: 10-K Note 14 (R89)
A11: Hardware revenue | B11: 3066 | C11: 2936 | D11: 3084 | J11: 10-K R4
A12: Services revenue | B12: 5431 | C12: 5233 | D12: 5743 | J12: 10-K R4
A13: TOTAL REVENUE | B13: 52961 | C13: 57399 | D13: 67357 | J13: 10-K R4
A14: Cost of cloud & software (ex intangible amort.) | B14: 9427 | C14: 11569 | D14: 17597 | J14: 10-K R4
A15: Cost of hardware | B15: 891 | C15: 782 | D15: 868 | J15: 10-K R4
A16: Cost of services | B16: 4825 | C16: 4576 | D16: 4556 | J16: 10-K R4
... A37: Share repurchases | B37: 1202 | C37: 600 | D37: 95 | J37: 10-K R8. $95m in FY26 vs $1,202m FY24 — buybacks have effectively stopped.
A38: GROSS PROFIT (derived) | B38: =B13-B14-B15-B16 | C38: =C13-C14-C15-C16 | D38: =D13-D14-D15-D16 | J38: Revenue less the three cost-of-revenue lines. Excludes intangible amortisation, per Oracle presentation.
A39: Gross margin % | B39: =B38/B13 | C39: =C38/C13 | D39: =D38/D13 | J39: FY22 79.08% -> FY23 72.85% -> FY24 71.41% -> FY25 70.51% -> FY26 65.82%. Five straight years of compression.
A41: DERIVED — IaaS gross margin (ANALYST ESTIMATE: Oracle does not disclose cost of revenue by offering)
A42: Assumed software support gross margin | D42: 0.93 | J42: Analyst estimate. Changes the derived IaaS margin one-for-one.
A43: Assumed software licence gross margin | D43: 0.98 | J43: Analyst estimate. Changes the derived IaaS margin one-for-one.
A44: Assumed SaaS gross margin | D44: 0.78 | J44: Analyst estimate. Changes the derived IaaS margin one-for-one.
A45: Implied software cost of revenue | B45: =B10*(1-$D$42)+B9*(1-$D$43) | C45: =C10*(1-$D$42)+C9*(1-$D$43) | D45: =D10*(1-$D$42)+D9*(1-$D$43)
A46: Implied cloud cost of revenue | B46: =B14-B45 | C46: =C14-C45 | D46: =D14-D45
A47: Implied IaaS cost of revenue | B47: =B46-B7*(1-$D$44) | C47: =C46-C7*(1-$D$44) | D47: =D46-D7*(1-$D$44)
A48: DERIVED IaaS GROSS MARGIN | B48: =1-B47/B6 | C48: =1-C47/C6 | D48: =1-D47/D6 | J48: ~30% in FY26A. This single number, and the asset turn, decide whether the buildout creates value.

Sheet RPO_Schedule
A1: RPO CONVERSION SCHEDULE — the disclosed 12 / 34 / 34 / 20 waterfall
A2: Oracle discloses the entire five-year conversion profile of the $638bn backlog in Note 1 of the FY26 10-K. Revenue through FY2031 is therefore largely a DISCLOSED SCHEDULE, not a forecast.
A4: $ millions | C4: FY2027E | D4: FY2028E | E4: FY2029E | F4: FY2030E | G4: FY2031E | J4: Note
A6: DISCLOSED BACKLOG AND CONVERSION PROFILE (10-K Note 1, verbatim)
A7: Remaining performance obligations at 5/31/2026 | B7: =Inputs!$B$9 | J7: DISCLOSED. Up 363% from $137.8bn.
A8: expected in the next 12 months (12%) | B8: =Inputs!$B$9*Inputs!$B$10
A9: expected in months 13–36 (34%) | B9: =Inputs!$B$9*Inputs!$B$11
A10: expected in months 37–60 (34%) | B10: =Inputs!$B$9*Inputs!$B$12
A11: thereafter (20%) | B11: =Inputs!$B$9*Inputs!$B$13
A13: DECOMPOSITION — legacy backlog vs the FY26 AI step-change (ANALYST CONSTRUCT)
A14: "Legacy" (pre-AI) backlog | B14: =Inputs!$B$14 | J14: ≈ the 5/31/2025 RPO of $137.8bn.
A15: AI backlog (the FY26 step-change) | B15: =B7-B14 | J15: RPO went $137.8bn -> $455.3bn in Q1 FY26 alone. Two-thirds of the backlog was signed in ONE quarter.
A16: Counterparty haircut applied to AI backlog | B16: =Inputs!$B$15 | J16: KEY LEVER.
A18: Legacy backlog conversion % | C18: =Inputs!C$16 | D18: =Inputs!D$16 | E18: =Inputs!E$16 | F18: =Inputs!F$16 | G18: =Inputs!G$16
A19: Legacy backlog revenue | C19: =$B$14*C18 | D19: =$B$14*D18 | E19: =$B$14*E18 | F19: =$B$14*F18 | G19: =$B$14*G18
A20: AI conversion in the m0–12 bucket | C20: =$B$8-C19
A21: AI conversion in the m13–36 bucket | C21: =$B$9-D19-E19
A22: AI conversion in the m37–60 bucket | C22: =$B$10-F19-G19
A23: AI backlog revenue (after haircut) | C23: =C20*(1-$B$16) | D23: =$C$21*Inputs!$B$17*(1-$B$16) | E23: =$C$21*(1-Inputs!$B$17)*(1-$B$16) | F23: =$C$22*Inputs!$B$18*(1-$B$16) | G23: =$C$22*(1-Inputs!$B$18)*(1-$B$16)
A24: REVENUE FROM THE 5/31/26 BACKLOG | C24: =C19+C23 | D24: =D19+D23 | E24: =E19+E23 | F24: =F19+F23 | G24: =G19+G23 | J24: Note the shape: a step up into FY28 and then a PLATEAU. The disclosed schedule allocates the same 34% to months 13–36 and 37–60. Every dollar of growth after FY2028 must come from contracts not yet signed.
A26: NEW BOOKINGS SIGNED AFTER 5/31/2026 (PURE ANALYST ESTIMATE — dominates FY30–31)
A27: New bookings | C27: =Inputs!C$19 | D27: =Inputs!D$19 | E27: =Inputs!E$19 | F27: =Inputs!F$19 | G27: =Inputs!G$19
A28: Conversion profile, year 1..5 | C28: =Inputs!C$20 | D28: =Inputs!D$20 | E28: =Inputs!E$20 | F28: =Inputs!F$20 | G28: =Inputs!G$20
A29: Revenue from new bookings | C29: =$C$27*$C$28 | D29: =$C$27*$D$28+$D$27*$C$28 | E29: =$C$27*$E$28+$D$27*$D$28+$E$27*$C$28 | F29: =$C$27*$F$28+$D$27*$E$28+$E$27*$D$28+$F$27*$C$28 | G29: =$C$27*$G$28+$D$27*$F$28+$E$27*$E$28+$F$27*$D$28+$G$27*$C$28
A30: Revenue not covered by RPO | C30: =Inputs!$B$21*(1+Inputs!$B$22)^1 | D30: =Inputs!$B$21*(1+Inputs!$B$22)^2 | E30: =Inputs!$B$21*(1+Inputs!$B$22)^3 | F30: =Inputs!$B$21*(1+Inputs!$B$22)^4 | G30: =Inputs!$B$21*(1+Inputs!$B$22)^5 | J30: Hardware, non-committed consumption, some services and new licence.
A31: TOTAL REVENUE | C31: =C24+C29+C30 | D31: =D24+D29+D30 | E31: =E24+E29+E30 | F31: =F24+F29+F30 | G31: =G24+G29+G30
A32: y/y growth | C32: =C31/Historicals!D13-1 | D32: =D31/C31-1 | E32: =E31/D31-1 | F32: =F31/E31-1 | G32: =G31/F31-1
A34: SEGMENT BUILD — IaaS is the residual
A35: Cloud applications (SaaS) | C35: =Historicals!D7*(1+Inputs!C$24) | D35: =C35*(1+Inputs!D$24) | E35: =D35*(1+Inputs!E$24) | F35: =E35*(1+Inputs!F$24) | G35: =F35*(1+Inputs!G$24)
A36: Software licence | C36: =Historicals!D9*(1+Inputs!C$25) | D36: =C36*(1+Inputs!D$25) | E36: =D36*(1+Inputs!E$25) | F36: =E36*(1+Inputs!F$25) | G36: =F36*(1+Inputs!G$25)
A37: Software support | C37: =Historicals!D10*(1+Inputs!C$26) | D37: =C37*(1+Inputs!D$26) | E37: =D37*(1+Inputs!E$26) | F37: =E37*(1+Inputs!F$26) | G37: =F37*(1+Inputs!G$26)
A38: Services | C38: =Historicals!D12*(1+Inputs!C$27) | D38: =C38*(1+Inputs!D$27) | E38: =D38*(1+Inputs!E$27) | F38: =E38*(1+Inputs!F$27) | G38: =F38*(1+Inputs!G$27)
A39: Hardware | C39: =Historicals!D11*(1+Inputs!C$28) | D39: =C39*(1+Inputs!D$28) | E39: =D39*(1+Inputs!E$28) | F39: =E39*(1+Inputs!F$28) | G39: =F39*(1+Inputs!G$28)
A40: Cloud infrastructure (IaaS) — RESIDUAL | C40: =C31-C35-C36-C37-C38-C39 | D40: =D31-D35-D36-D37-D38-D39 | E40: =E31-E35-E36-E37-E38-E39 | F40: =F31-F35-F36-F37-F38-F39 | G40: =G31-G35-G36-G37-G38-G39 | J40: IaaS = total revenue less the five modelled lines. FY26A $18,101m.
A41: IaaS y/y growth | C41: =C40/Historicals!D6-1 | D41: =D40/C40-1 | E41: =E40/D40-1 | F41: =F40/E40-1 | G41: =G40/F40-1
A42: MEMO: revenue guidance FY2027 | C42: 90000 | J42: DISCLOSED: "we confirm our prior revenue guidance of $90 billion total revenue" — press release 6/10/2026.
A43: MEMO: consensus FY2027 revenue | C43: 89340 | J43: stockanalysis.com, 42 analysts, pulled 8/27–28/2026.

Sheet Capex_Depreciation
A1: CAPEX -> CIP -> IN-SERVICE -> DEPRECIATION WATERFALL
A2: Capex is LINKED to the IaaS revenue it must serve, not set as a % of revenue. 32.6% of gross PP&E at 5/31/26 ($39,973m) was construction in progress and NOT YET DEPRECIATING.
A4: $ millions | C4: FY2027E | D4: FY2028E | E4: FY2029E | F4: FY2030E | G4: FY2031E | J4: Note
A6: CAPACITY REQUIREMENT
A7: IaaS revenue | C7: =RPO_Schedule!C40 | D7: =RPO_Schedule!D40 | E7: =RPO_Schedule!E40 | F7: =RPO_Schedule!F40 | G7: =RPO_Schedule!G40
A8: IaaS revenue, following year | C8: =D7 | D8: =E7 | E8: =F7 | F8: =G7 | G8: =G7*(1+Inputs!$B$51) | J8: FY32 is required to size FY31 capex.
A9: Effective asset turn (turn x utilisation) | C9: =Inputs!$B$46*Inputs!C$47 | D9: =Inputs!$B$46*Inputs!D$47 | E9: =Inputs!$B$46*Inputs!E$47 | F9: =Inputs!$B$46*Inputs!F$47 | G9: =Inputs!$B$46*Inputs!G$47 | J9: KEY LEVER. IaaS revenue generated per $1 of gross PP&E. Not disclosed by Oracle anywhere.
A10: Gross capacity to add | C10: =MAX(0,C8-C7)/C9 | D10: =MAX(0,D8-D7)/D9 | E10: =MAX(0,E8-E7)/E9 | F10: =MAX(0,F8-F7)/F9 | G10: =MAX(0,G8-G7)/G9
A11: funded by customers (prepay + customer GPUs) | C11: =C10*Inputs!C$48 | D11: =D10*Inputs!D$48 | E11: =E10*Inputs!E$48 | F11: =F10*Inputs!F$48 | G11: =G10*Inputs!G$48 | J11: Anchored to management: prepaid + customer-supplied hardware "now total $75 billion" (press release 6/10/26).
A12: ORACLE-FUNDED GROWTH CAPEX | C12: =C10-C11 | D12: =D10-D11 | E12: =E10-E11 | F12: =F10-F11 | G12: =G10-G11
A14: PASS 1 — provisional depreciation, used only to size maintenance capex
A15: Annual depreciation rate on a $1 vintage | C15: =Inputs!$B$52/Inputs!$B$55+Inputs!$B$53/Inputs!$B$56 | D15: =Inputs!$B$52/Inputs!$B$55+Inputs!$B$53/Inputs!$B$56 | E15: =Inputs!$B$52/Inputs!$B$55+Inputs!$B$53/Inputs!$B$56 | F15: =Inputs!$B$52/Inputs!$B$55+Inputs!$B$53/Inputs!$B$56 | G15: =Inputs!$B$52/Inputs!$B$55+Inputs!$B$53/Inputs!$B$56 | J15: Equipment 6-yr (10-K R50: servers and networking equipment) + buildings 25-yr. Land does not depreciate.
A16: CIP released into service | C16: =Inputs!$B$57*Inputs!$B$58 | D16: =Inputs!$B$57*Inputs!$B$59 | E16: 0 | F16: 0 | G16: 0 | J16: The $39,973m CIP balance at 5/31/26 begins depreciating. This alone is the single largest driver of the FY27 margin guide-down.
A17: Provisional in-service additions | C17: =C16+Inputs!$B$60*C12 | D17: =D16+Inputs!$B$60*D12+Inputs!$B$61*C12 | E17: =E16+Inputs!$B$60*E12+Inputs!$B$61*D12 | F17: =F16+Inputs!$B$60*F12+Inputs!$B$61*E12 | G17: =G16+Inputs!$B$60*G12+Inputs!$B$61*F12
A18: Provisional depreciation on new vintages | C18: =$C$17*$C$15*0.5 | D18: =$C$17*$C$15*1+$D$17*$C$15*0.5 | E18: =$C$17*$C$15*1+$D$17*$C$15*1+$E$17*$C$15*0.5 | F18: =$C$17*$C$15*1+$D$17*$C$15*1+$E$17*$C$15*1+$F$17*$C$15*0.5 | G18: =$C$17*$C$15*1+$D$17*$C$15*1+$E$17*$C$15*1+$F$17*$C$15*1+$G$17*$C$15*0.5
A19: Depreciation on the existing in-service base | C19: =((Inputs!$B$57*0+122651-Inputs!$B$57)-22694)/Inputs!$B$62 | D19: =((Inputs!$B$57*0+122651-Inputs!$B$57)-22694)/Inputs!$B$62 | E19: =((Inputs!$B$57*0+122651-Inputs!$B$57)-22694)/Inputs!$B$62 | F19: =((Inputs!$B$57*0+122651-Inputs!$B$57)-22694)/Inputs!$B$62 | G19: =((Inputs!$B$57*0+122651-Inputs!$B$57)-22694)/Inputs!$B$62 | J19: Gross PP&E $122,651m less CIP $39,973m = $82,678m in service; less accumulated depreciation $22,694m = $59,984m NBV (10-K R49), over 5 years.
A20: Provisional total depreciation | C20: =C18+C19 | D20: =D18+D19 | E20: =E18+E19 | F20: =F18+F19 | G20: =G18+G19
A21: Maintenance capex | C21: =C20*Inputs!C$49 | D21: =D20*Inputs!D$49 | E21: =E20*Inputs!E$49 | F21: =F20*Inputs!F$49 | G21: =G20*Inputs!G$49
A22: Committed capex floor | C22: =Inputs!C$50 | D22: =Inputs!D$50 | E22: =Inputs!E$50 | F22: =Inputs!F$50 | G22: =Inputs!G$50 | J22: GPU/server orders and data-centre leases placed 12–18 months ahead. This is what turns a demand shortfall into a funding problem.
A23: TOTAL CAPEX | C23: =MAX(C12+C21,C22) | D23: =MAX(D12+D21,D22) | E23: =MAX(E12+E21,E22) | F23: =MAX(F12+F21,F22) | G23: =MAX(G12+G21,G22)
A24: 3-year rolling average | D24: =AVERAGE($C$23:D23) | E24: =AVERAGE($C$23:E23) | F24: =AVERAGE(D23:F23) | G24: =AVERAGE(E23:G23) | J24: The annual path is lumpy BY CONSTRUCTION because the disclosed RPO conversion schedule is lumpy. Smoothing it would hide the mechanism.
A26: PASS 2 — final depreciation vintage waterfall
A27: In-service additions | C27: =C16+Inputs!$B$60*C23 | D27: =D16+Inputs!$B$60*D23+Inputs!$B$61*C23 | E27: =E16+Inputs!$B$60*E23+Inputs!$B$61*D23 | F27: =F16+Inputs!$B$60*F23+Inputs!$B$61*E23 | G27: =G16+Inputs!$B$60*G23+Inputs!$B$61*F23
A28: depreciation on the FY2027 vintage | C28: =$C$27*$C$15*0.5 | D28: =$C$27*$C$15*1 | E28: =$C$27*$C$15*1 | F28: =$C$27*$C$15*1 | G28: =$C$27*$C$15*1
A29: depreciation on the FY2028 vintage | D29: =$D$27*$C$15*0.5 | E29: =$D$27*$C$15*1 | F29: =$D$27*$C$15*1 | G29: =$D$27*$C$15*1
A30: depreciation on the FY2029 vintage | E30: =$E$27*$C$15*0.5 | F30: =$E$27*$C$15*1 | G30: =$E$27*$C$15*1
A31: depreciation on the FY2030 vintage | F31: =$F$27*$C$15*0.5 | G31: =$F$27*$C$15*1
A32: depreciation on the FY2031 vintage | G32: =$G$27*$C$15*0.5
A33: Depreciation on the existing in-service base | C33: =C19 | D33: =D19 | E33: =E19 | F33: =F19 | G33: =G19
A34: Less: relief from impaired assets | C34: =0 | D34: =-SUM(Inputs!C$43)/5 | E34: =-SUM(Inputs!C$43,Inputs!D$43)/5 | F34: =-SUM(Inputs!C$43,Inputs!D$43,Inputs!E$43)/5 | G34: =-SUM(Inputs!C$43,Inputs!D$43,Inputs!E$43,Inputs!F$43)/5
A35: TOTAL DEPRECIATION | C35: =SUM(C28:C32)+C33+C34 | D35: =SUM(D28:D32)+D33+D34 | E35: =SUM(E28:E32)+E33+E34 | F35: =SUM(F28:F32)+F33+F34 | G35: =SUM(G28:G32)+G33+G34 | J35: FY2026A was $7,623m. The step-up is the mechanical core of the whole story.
A37: PP&E ROLL-FORWARD
A38: Gross PP&E, opening | C38: =122651 | D38: =C39 | E38: =D39 | F38: =E39 | G38: =F39
A39: Gross PP&E, closing | C39: =C38+C23 | D39: =D38+D23 | E39: =E38+E23 | F39: =F38+F23 | G39: =G38+G23
A40: Accumulated depreciation, closing | C40: =22694+SUM($C$35:C35) | D40: =22694+SUM($C$35:D35) | E40: =22694+SUM($C$35:E35) | F40: =22694+SUM($C$35:F35) | G40: =22694+SUM($C$35:G35)
A41: Cumulative impairment | C41: =SUM(Inputs!$C$43:C$43) | D41: =SUM(Inputs!$C$43:D$43) | E41: =SUM(Inputs!$C$43:E$43) | F41: =SUM(Inputs!$C$43:F$43) | G41: =SUM(Inputs!$C$43:G$43)
A42: NET PP&E | C42: =C39-C40-C41 | D42: =D39-D40-D41 | E42: =E39-E40-E41 | F42: =F39-F40-F41 | G42: =G39-G40-G41 | J42: FY2026A $99,957m (10-K R2).
A43: Construction in progress, closing | C43: =MAX(0,Inputs!$B$57+C23-C27) | D43: =MAX(0,C43+D23-D27) | E43: =MAX(0,D43+E23-E27) | F43: =MAX(0,E43+F23-F27) | G43: =MAX(0,F43+G23-G27) | J43: FY2026A $39,973m (10-K R49).
A44: Cumulative capex FY27 onwards | C44: =SUM($C$23:C23) | D44: =SUM($C$23:D23) | E44: =SUM($C$23:E23) | F44: =SUM($C$23:F23) | G44: =SUM($C$23:G23)

Sheet Income_Statement
A1: INCOME STATEMENT — GAAP, FY2027E–FY2031E
A2: Depreciation sits inside cost of revenue, as Oracle reports it. That is why the buildout hits gross margin, non-GAAP EPS and GAAP EPS alike.
A4: $ millions | C4: FY2027E | D4: FY2028E | E4: FY2029E | F4: FY2030E | G4: FY2031E | J4: Note
A6: REVENUE
A7: Cloud infrastructure (IaaS) | C7: =RPO_Schedule!C40 | D7: =RPO_Schedule!D40 | E7: =RPO_Schedule!E40 | F7: =RPO_Schedule!F40 | G7: =RPO_Schedule!G40
A8: Cloud applications (SaaS) | C8: =RPO_Schedule!C35 | D8: =RPO_Schedule!D35 | E8: =RPO_Schedule!E35 | F8: =RPO_Schedule!F35 | G8: =RPO_Schedule!G35
A9: Software licence | C9: =RPO_Schedule!C36 | D9: =RPO_Schedule!D36 | E9: =RPO_Schedule!E36 | F9: =RPO_Schedule!F36 | G9: =RPO_Schedule!G36
A10: Software support | C10: =RPO_Schedule!C37 | D10: =RPO_Schedule!D37 | E10: =RPO_Schedule!E37 | F10: =RPO_Schedule!F37 | G10: =RPO_Schedule!G37
A11: Services | C11: =RPO_Schedule!C38 | D11: =RPO_Schedule!D38 | E11: =RPO_Schedule!E38 | F11: =RPO_Schedule!F38 | G11: =RPO_Schedule!G38
A12: Hardware | C12: =RPO_Schedule!C39 | D12: =RPO_Schedule!D39 | E12: =RPO_Schedule!E39 | F12: =RPO_Schedule!F39 | G12: =RPO_Schedule!G39
A13: TOTAL REVENUE | C13: =SUM(C7:C12) | D13: =SUM(D7:D12) | E13: =SUM(E7:E12) | F13: =SUM(F7:F12) | G13: =SUM(G7:G12)
A14: y/y growth | C14: =C13/Historicals!D13-1 | D14: =D13/C13-1 | E14: =E13/D13-1 | F14: =F13/E13-1 | G14: =G13/F13-1
A16: COST OF REVENUE
A17: Depreciation charged to IaaS | C17: =Capex_Depreciation!C35*Inputs!C$31 | D17: =Capex_Depreciation!D35*Inputs!D$31 | E17: =Capex_Depreciation!E35*Inputs!E$31 | F17: =Capex_Depreciation!F35*Inputs!F$31 | G17: =Capex_Depreciation!G35*Inputs!G$31 | J17: The buildout arrives here. Oracle does NOT exclude depreciation from non-GAAP.
A18: IaaS cost ex-depreciation | C18: =C7*Inputs!C$30 | D18: =D7*Inputs!D$30 | E18: =E7*Inputs!E$30 | F18: =F7*Inputs!F$30 | G18: =G7*Inputs!G$30 | J18: KEY LEVER.
A19: Cost of IaaS | C19: =C17+C18 | D19: =D17+D18 | E19: =E17+E18 | F19: =F17+F18 | G19: =G17+G18
A20: Cost of SaaS | C20: =C8*(1-Inputs!C$32) | D20: =D8*(1-Inputs!D$32) | E20: =E8*(1-Inputs!E$32) | F20: =F8*(1-Inputs!F$32) | G20: =G8*(1-Inputs!G$32)
A21: Cost of software | C21: =C10*(1-Inputs!C$33)+C9*(1-Inputs!C$34) | D21: =D10*(1-Inputs!D$33)+D9*(1-Inputs!D$34) | E21: =E10*(1-Inputs!E$33)+E9*(1-Inputs!E$34) | F21: =F10*(1-Inputs!F$33)+F9*(1-Inputs!F$34) | G21: =G10*(1-Inputs!G$33)+G9*(1-Inputs!G$34)
A22: Cost of services | C22: =C11*(1-Inputs!C$35) | D22: =D11*(1-Inputs!D$35) | E22: =E11*(1-Inputs!E$35) | F22: =F11*(1-Inputs!F$35) | G22: =G11*(1-Inputs!G$35)
A23: Cost of hardware | C23: =C12*(1-Inputs!C$36) | D23: =D12*(1-Inputs!D$36) | E23: =E12*(1-Inputs!E$36) | F23: =F12*(1-Inputs!F$36) | G23: =G12*(1-Inputs!G$36)
A24: TOTAL COST OF REVENUE | C24: =SUM(C19:C23) | D24: =SUM(D19:D23) | E24: =SUM(E19:E23) | F24: =SUM(F19:F23) | G24: =SUM(G19:G23)
A25: GROSS PROFIT | C25: =C13-C24 | D25: =D13-D24 | E25: =E13-E24 | F25: =F13-F24 | G25: =G13-G24
A26: gross margin | C26: =C25/C13 | D26: =D25/D13 | E26: =E25/E13 | F26: =F25/F13 | G26: =G25/G13 | J26: FY2026A 65.82%. Consensus FY2027E 59.98%.
A27: IaaS gross margin (memo) | C27: =1-C19/C7 | D27: =1-D19/D7 | E27: =1-E19/E7 | F27: =1-F19/F7 | G27: =1-G19/G7 | J27: FY2026A ~30% (derived on the Historicals tab).
A29: OPERATING EXPENSE
A30: Sales & marketing | C30: =C13*Inputs!C$38 | D30: =D13*Inputs!D$38 | E30: =E13*Inputs!E$38 | F30: =F13*Inputs!F$38 | G30: =G13*Inputs!G$38 | J30: FY2026A $8,331m = 12.4% of revenue.
A31: Research & development | C31: =Historicals!D18*(1+Inputs!C$39) | D31: =C31*(1+Inputs!D$39) | E31: =D31*(1+Inputs!E$39) | F31: =E31*(1+Inputs!F$39) | G31: =F31*(1+Inputs!G$39)
A32: General & administrative | C32: =Historicals!D19*(1+Inputs!C$40) | D32: =C32*(1+Inputs!D$40) | E32: =D32*(1+Inputs!E$40) | F32: =E32*(1+Inputs!F$40) | G32: =F32*(1+Inputs!G$40)
A33: Amortisation of intangible assets | C33: =Inputs!C$44 | D33: =Inputs!D$44 | E33: =Inputs!E$44 | F33: =Inputs!F$44 | G33: =Inputs!G$44 | J33: DISCLOSED in full: 10-K R53 gives FY27–FY31 amortisation. No estimate required.
A34: Restructuring, other and impairment | C34: =Inputs!C$42+Inputs!C$43 | D34: =Inputs!D$42+Inputs!D$43 | E34: =Inputs!E$42+Inputs!E$43 | F34: =Inputs!F$42+Inputs!F$43 | G34: =Inputs!G$42+Inputs!G$43
A35: GAAP OPERATING INCOME | C35: =C25-C30-C31-C32-C33-C34 | D35: =D25-D30-D31-D32-D33-D34 | E35: =E25-E30-E31-E32-E33-E34 | F35: =F25-F30-F31-F32-F33-F34 | G35: =G25-G30-G31-G32-G33-G34
A36: operating margin | C36: =C35/C13 | D36: =D35/D13 | E36: =E35/E13 | F36: =F35/F13 | G36: =G35/G13
A38: BELOW THE LINE
A39: Interest expense | C39: =-Debt_Shares!C11 | D39: =-Debt_Shares!D11 | E39: =-Debt_Shares!E11 | F39: =-Debt_Shares!F11 | G39: =-Debt_Shares!G11 | J39: FY2026A $(4,599)m.
A40: Interest income | C40: =Debt_Shares!C17 | D40: =Debt_Shares!D17 | E40: =Debt_Shares!E17 | F40: =Debt_Shares!F17 | G40: =Debt_Shares!G17
A41: Other non-operating (FX, NCI) | C41: -250 | D41: -250 | E41: -250 | F41: -250 | G41: -250 | J41: FY2026A non-operating income was +$3,547m, but $2,811m of that was one-time investment gains (Ampere, Bloom warrants). No repeat is assumed.
A42: PRETAX INCOME | C42: =C35+C39+C40+C41 | D42: =D35+D39+D40+D41 | E42: =E35+E39+E40+E41 | F42: =F35+F39+F40+F41 | G42: =G35+G39+G40+G41
A43: Provision for income taxes | C43: =-C42*Inputs!C$69 | D43: =-D42*Inputs!D$69 | E43: =-E42*Inputs!E$69 | F43: =-F42*Inputs!F$69 | G43: =-G42*Inputs!G$69 | J43: FY2026A effective rate 12.6%, which included a $2,062m stock-compensation windfall benefit (10-K R80). At $151.94 versus a $345.72 52-week high, that benefit does not repeat.
A44: NET INCOME | C44: =C42+C43 | D44: =D42+D43 | E44: =E42+E43 | F44: =F42+F43 | G44: =G42+G43
A45: Preferred dividends | C45: =-Debt_Shares!C27 | D45: =-Debt_Shares!D27 | E45: =-Debt_Shares!E27 | F45: =-Debt_Shares!F27 | G45: =-Debt_Shares!G27
...

Sheet NonGAAP_Recon
A1: GAAP <-> NON-GAAP RECONCILIATION
A2: Oracle excludes SBC, intangible amortisation and restructuring — and RE-TAXES the result at a HIGHER rate than its GAAP effective rate. That tax wedge is a real part of why non-GAAP EPS growth lags revenue growth.
A4: $ millions | B4: FY2026A | C4: FY2027E | D4: FY2028E | E4: FY2029E | F4: FY2030E | G4: FY2031E | J4: Note
B5: GAAP | C5: Adjustment | D5: Non-GAAP
A6: FY2026 ACTUAL BRIDGE (press release Ex-99.1, verbatim)
A7: Total operating expenses | B7: 46751 | C7: -8320 | D7: 38431 | J7: Add-backs: SBC $4,811m + intangible amortisation $1,671m + restructuring $1,838m = $8,320m.
A8: Operating income | B8: 20606 | C8: 8320 | D8: 28926 | J8: GAAP margin 31%, non-GAAP margin 43%.
A9: Provision for income taxes | B9: 2467 | C9: 3070 | D9: 5537 | J9: GAAP effective rate 12.6%; non-GAAP effective rate 19.9%. The non-GAAP rate is HIGHER.
A10: Net income | B10: 17087 | C10: 5250 | D10: 22337
A11: Net income available to common | B11: 16984 | C11: 5250 | D11: 22234
A12: Diluted EPS | B12: 5.83 | C12: 1.8 | D12: 7.63 | J12: Diluted share count is IDENTICAL on both bases: 2,914m.
A13: Non-GAAP EPS excluding one-time investment gains | D13: 6.83 | J13: DISCLOSED: press release footnote 1 — the $7.63 headline includes gains on the Ampere sale and Bloom Energy warrants. $6.83 is the clean base, and it is the base management itself uses for the "+18%" FY27 growth claim.
A15: FORECAST BRIDGE
A16: GAAP operating income | C16: =Income_Statement!C35 | D16: =Income_Statement!D35 | E16: =Income_Statement!E35 | F16: =Income_Statement!F35 | G16: =Income_Statement!G35
A17: + Stock-based compensation | C17: =Historicals!D34*(1+Inputs!C$41) | D17: =C17*(1+Inputs!D$41) | E17: =D17*(1+Inputs!E$41) | F17: =E17*(1+Inputs!F$41) | G17: =F17*(1+Inputs!G$41) | J17: FY2026A $4,811m.
A18: + Amortisation of intangible assets | C18: =Income_Statement!C33 | D18: =Income_Statement!D33 | E18: =Income_Statement!E33 | F18: =Income_Statement!F33 | G18: =Income_Statement!G33
A19: + Restructuring, other and impairment | C19: =Income_Statement!C34 | D19: =Income_Statement!D34 | E19: =Income_Statement!E34 | F19: =Income_Statement!F34 | G19: =Income_Statement!G34 | J19: In the bear case the asset write-downs land HERE — inside the very line Oracle excludes. Non-GAAP EPS barely moves while GAAP EPS collapses.
A20: NON-GAAP OPERATING INCOME | C20: =C16+C17+C18+C19 | D20: =D16+D17+D18+D19 | E20: =E16+E17+E18+E19 | F20: =F16+F17+F18+F19 | G20: =G16+G17+G18+G19
A21: non-GAAP operating margin | C21: =C20/Income_Statement!C13 | D21: =D20/Income_Statement!D13 | E21: =E20/Income_Statement!E13 | F21: =F20/Income_Statement!F13 | G21: =G20/Income_Statement!G13
A22: Non-GAAP pretax income | C22: =Income_Statement!C42+C17+C18+C19 | D22: =Income_Statement!D42+D17+D18+D19 | E22: =Income_Statement!E42+E17+E18+E19 | F22: =Income_Statement!F42+F17+F18+F19 | G22: =Income_Statement!G42+G17+G18+G19
A23: Non-GAAP tax | C23: =-C22*Inputs!C$70 | D23: =-D22*Inputs!D$70 | E23: =-E22*Inputs!E$70 | F23: =-F22*Inputs!F$70 | G23: =-G22*Inputs!G$70 | J23: FY2026A 19.9%, ABOVE the 12.6% GAAP rate.
A24: Non-GAAP net income | C24: =C22+C23 | D24: =D22+D23 | E24: =E22+E23 | F24: =F22+F23 | G24: =G22+G23
A25: Less preferred dividends | C25: =Income_Statement!C45 | D25: =Income_Statement!D45 | E25: =Income_Statement!E45 | F25: =Income_Statement!F45 | G25: =Income_Statement!G45
A26: NON-GAAP EPS | C26: =(C24+C25)/Income_Statement!C47 | D26: =(D24+D25)/Income_Statement!D47 | E26: =(E24+E25)/Income_Statement!E47 | F26: =(F24+F25)/Income_Statement!F47 | G26: =(G24+G25)/Income_Statement!G47
A27: MEMO: FY2027 non-GAAP EPS GUIDANCE | C27: 8.05 | J27: DISCLOSED: press release 6/10/2026 — "raise our non-GAAP EPS guidance to $8.05". Guidance, not consensus.
A28: MEMO: FY2027 consensus non-GAAP EPS | C28: 8.05 | J28: stockanalysis.com, 42 analysts: low $7.72 / avg $8.05 / high $8.57. Consensus sits ON guidance — that is herding, not conviction.
A29: GAAP EPS (memo) | C29: =Income_Statement!C48 | D29: =Income_Statement!D48 | E29: =Income_Statement!E48 | F29: =Income_Statement!F48 | G29: =Income_Statement!G48

Sheet Cash_Flow
A1: CASH FLOW — and the three different "capex" numbers
A2: The cash statement, not the income statement, is the headline output. FY2026A: OCF $31,977m, capex $(55,663)m, FCF $(23,686)m — Oracle's own published figure.
A4: $ millions | C4: FY2027E | D4: FY2028E | E4: FY2029E | F4: FY2030E | G4: FY2031E | J4: Note
A6: OPERATING
A7: Net income | C7: =Income_Statement!C44 | D7: =Income_Statement!D44 | E7: =Income_Statement!E44 | F7: =Income_Statement!F44 | G7: =Income_Statement!G44
A8: + Depreciation | C8: =Capex_Depreciation!C35 | D8: =Capex_Depreciation!D35 | E8: =Capex_Depreciation!E35 | F8: =Capex_Depreciation!F35 | G8: =Capex_Depreciation!G35
A9: + Amortisation of intangible assets | C9: =Income_Statement!C33 | D9: =Income_Statement!D33 | E9: =Income_Statement!E33 | F9: =Income_Statement!F33 | G9: =Income_Statement!G33
A10: + Stock-based compensation | C10: =NonGAAP_Recon!C17 | D10: =NonGAAP_Recon!D17 | E10: =NonGAAP_Recon!E17 | F10: =NonGAAP_Recon!F17 | G10: =NonGAAP_Recon!G17
A11: + Asset impairment (non-cash) | C11: =Inputs!C$43 | D11: =Inputs!D$43 | E11: =Inputs!E$43 | F11: =Inputs!F$43 | G11: =Inputs!G$43
A12: - Increase in net working capital | C12: =-(Income_Statement!C13-Historicals!D13)*Inputs!$B$77 | D12: =-(Income_Statement!D13-Income_Statement!C13)*Inputs!$B$77 | E12: =-(Income_Statement!E13-Income_Statement!D13)*Inputs!$B$77 | F12: =-(Income_Statement!F13-Income_Statement!E13)*Inputs!$B$77 | G12: =-(Income_Statement!G13-Income_Statement!F13)*Inputs!$B$77
A13: + Customer prepayments | C13: =Inputs!C$75 | D13: =Inputs!D$75 | E13: =Inputs!E$75 | F13: =Inputs!F$75 | G13: =Inputs!G$75 | J13: FY2026A $4,592m — a brand-new line in the FY26 cash flow statement (10-K R8). These are prepayments with a significant financing component on AI contracts, i.e. customers funding Oracle's buildout.
A14: OPERATING CASH FLOW | C14: =SUM(C7:C13) | D14: =SUM(D7:D13) | E14: =SUM(E7:E13) | F14: =SUM(F7:F13) | G14: =SUM(G7:G13) | J14: FY2026A $31,977m, +54%.
A16: THE THREE CAPEX DEFINITIONS — pin this down before quoting any cash-flow gap
A17: (1) Capital expenditures, as reported | C17: =-Capex_Depreciation!C23 | D17: =-Capex_Depreciation!D23 | E17: =-Capex_Depreciation!E23 | F17: =-Capex_Depreciation!F23 | G17: =-Capex_Depreciation!G23 | J17: The GAAP cash-flow-statement line. FY2026A $(55,663)m.
A18: add back: short-term financing related to capex | C18: =Inputs!C$76 | D18: =Inputs!D$76 | E18: =Inputs!E$76 | F18: =Inputs!F$76 | G18: =Inputs!G$76 | J18: FY2026A $3,345m, reported inside FINANCING activities (10-K R8).
A19: add back: customer prepayments for capex | C19: =Inputs!C$75 | D19: =Inputs!D$75 | E19: =Inputs!E$75 | F19: =Inputs!F$75 | G19: =Inputs!G$75 | J19: FY2026A $4,592m, reported inside OPERATING activities.
A20: (2) Net cash outlay for capex (Oracle non-GAAP) | C20: =C17+C18+C19 | D20: =D17+D18+D19 | E20: =E17+E18+E19 | F20: =F17+F18+F19 | G20: =G17+G18+G19 | J20: ORACLE'S OWN DEFINITION, press release Ex-99.1. FY2026A $(47,726)m. NOTE: consensus shows FY2027E free cash flow of $(47.73)bn — numerically IDENTICAL to Oracle's FY2026 ACTUAL net capex outlay. Treat that coincidence as a data-quality warning.
A21: (3) Economic capex incl. change in unpaid capex | C21: =C17 | D21: =D17 | E21: =E17 | F21: =F17 | G21: =G17 | J21: FY2026A: $(55,663)m cash + $5,279m unpaid at year end less $2,970m at prior year end = $(57,972)m economic. Not forecast here.
A22: FREE CASH FLOW (OCF less reported capex) | C22: =C14+C17 | D22: =D14+D17 | E22: =E14+E17 | F22: =F14+F17 | G22: =G14+G17 | J22: FY2026A $(23,686)m — this is the number Oracle itself publishes.
A23: FREE CASH FLOW (on Oracle's net-capex definition) | C23: =C14-C19+C20 | D23: =D14-D19+D20 | E23: =E14-E19+E20 | F23: =F14-F19+F20 | G23: =G14-G19+G20
A24: FCF margin | C24: =C22/Income_Statement!C13 | D24: =D22/Income_Statement!D13 | E24: =E22/Income_Statement!E13 | F24: =F22/Income_Statement!F13 | G24: =G22/Income_Statement!G13
A26: FINANCING AND THE FUNDING PLUG
A27: Common dividends | C27: =-Inputs!C$71*Debt_Shares!C26 | D27: =-Inputs!D$71*Debt_Shares!D26 | E27: =-Inputs!E$71*Debt_Shares!E26 | F27: =-Inputs!F$71*Debt_Shares!F26 | G27: =-Inputs!G$71*Debt_Shares!G26 | J27: DISCLOSED: $0.50/qtr declared 6/10/26 — FLAT versus FY26. After 12 consecutive years of growth, dividend growth has stopped.
A28: Preferred dividends | C28: =-Debt_Shares!C27 | D28: =-Debt_Shares!D27 | E28: =-Debt_Shares!E27 | F28: =-Debt_Shares!F27 | G28: =-Debt_Shares!G27
A29: Scheduled debt repayments | C29: =Debt_Shares!C8 | D29: =Debt_Shares!D8 | E29: =Debt_Shares!E8 | F29: =Debt_Shares!F8 | G29: =Debt_Shares!G8
A30: Equity issuance (ATM) | C30: =Inputs!C$67 | D30: =Inputs!D$67 | E30: =Inputs!E$67 | F30: =Inputs!F$67 | G30: =Inputs!G$67
A31: Short-term financing related to capex | C31: =Inputs!C$76 | D31: =Inputs!D$76 | E31: =Inputs!E$76 | F31: =Inputs!F$76 | G31: =Inputs!G$76
A32: Target cash cushion build | C32: 3000 | D32: 3000 | E32: 3000 | F32: 3000 | G32: 3000
A33: FUNDING NEED (= new debt required) | C33: =-(C14+C17+C27+C28+C29+C30+C31)+C32 | D33: =-(D14+D17+D27+D28+D29+D30+D31)+D32 | E33: =-(E14+E17+E27+E28+E29+E30+E31)+E32 | F33: =-(F14+F17+F27+F28+F29+F30+F31)+F32 | G33: =-(G14+G17+G27+G28+G29+G30+G31)+G32 | J33: Drives the new-debt plug on Debt_Shares.
A34: New debt issued | C34: =Debt_Shares!C12 | D34: =Debt_Shares!D12 | E34: =Debt_Shares!E12 | F34: =Debt_Shares!F12 | G34: =Debt_Shares!G12
A35: Cash, opening | C35: =Inputs!$B$79 | D35: =C36 | E35: =D36 | F35: =E36 | G35: =F36
A36: CASH, CLOSING | C36: =C35+C14+C17+C27+C28+C29+C30+C31+C34 | D36: =D35+D14+D17+D27+D28+D29+D30+D31+D34 | E36: =E35+E14+E17+E27+E28+E29+E30+E31+E34 | F36: =F35+F14+F17+F27+F28+F29+F30+F31+F34 | G36: =G35+G14+G17+G27+G28+G29+G30+G31+G34
A38: CREDIT METRICS
A39: Net debt | C39: =Debt_Shares!C16 | D39: =Debt_Shares!D16 | E39: =Debt_Shares!E16 | F39: =Debt_Shares!F16 | G39: =Debt_Shares!G16
A40: Net debt / EBITDA | C40: =Debt_Shares!C16/Income_Statement!C49 | D40: =Debt_Shares!D16/Income_Statement!D49 | E40: =Debt_Shares!E16/Income_Statement!E49 | F40: =Debt_Shares!F16/Income_Statement!F49 | G40: =Debt_Shares!G16/Income_Statement!G49 | J40: S&P cut Oracle to BBB- on 7/9/2026 (UNVERIFIED SECONDARY — from the user brief, not confirmed at source).
A41: EBITDA / net interest expense | C41: =IFERROR(Income_Statement!C49/(Debt_Shares!C11-Debt_Shares!C17),"n/m") | D41: =IFERROR(Income_Statement!D49/(Debt_Shares!D11-Debt_Shares!D17),"n/m") | E41: =IFERROR(Income_Statement!E49/(Debt_Shares!E11-Debt_Shares!E17),"n/m") | F41: =IFERROR(Income_Statement!F49/(Debt_Shares!F11-Debt_Shares!F17),"n/m") | G41: =IFERROR(Income_Statement!G49/(Debt_Shares!G11-Debt_Shares!G17),"n/m") | J41: The revolving credit agreement carries a consolidated EBITDA / consolidated net interest expense covenant of 3.0x (10-K R58).

Sheet Debt_Shares
A1: DEBT SCHEDULE, INTEREST, AND SHARE COUNT
A2: Interest is charged on OPENING balances only, which removes the circular reference. See Formula_Audit for the size of that simplification.
A4: $ millions | C4: FY2027E | D4: FY2028E | E4: FY2029E | F4: FY2030E | G4: FY2031E | J4: Note
A6: DEBT
A7: Total debt, opening | C7: =Inputs!$B$78 | D7: =C14 | E7: =D14 | F7: =E14 | G7: =F14 | J7: 10-K R2: $7,199m current + $122,342m non-current.
A8: Scheduled maturities | C8: =-Inputs!C$80 | D8: =-Inputs!D$80 | E8: =-Inputs!E$80 | F8: =-Inputs!F$80 | G8: =-Inputs!G$80 | J8: DISCLOSED in full: 10-K R57.
A9: Cumulative new debt, opening | C9: 0 | D9: =C13 | E9: =D13 | F9: =E13 | G9: =F13
A10: Estimated new debt this year (used only to charge interest) | C10: =MAX(0,Capex_Depreciation!C23+Inputs!C$80+Inputs!C$71*C26+3000-(Income_Statement!C36*(1-Inputs!C$69)+Capex_Depreciation!C35+Income_Statement!C34+NonGAAP_Recon!C18+Cash_Flow!C12+Inputs!C$75)-Inputs!C$67-Inputs!C$76) | D10: =MAX(0,Capex_Depreciation!D23+Inputs!D$80+Inputs!D$71*D26+3000-(Income_Statement!D36*(1-Inputs!D$69)+Capex_Depreciation!D35+Income_Statement!D34+NonGAAP_Recon!D18+Cash_Flow!D12+Inputs!D$75)-Inputs!D$67-Inputs!D$76) | E10: =MAX(0,Capex_Depreciation!E23+Inputs!E$80+Inputs!E$71*E26+3000-(Income_Statement!E36*(1-Inputs!E$69)+Capex_Depreciation!E35+Income_Statement!E34+NonGAAP_Recon!E18+Cash_Flow!E12+Inputs!E$75)-Inputs!E$67-Inputs!E$76) | F10: =MAX(0,Capex_Depreciation!F23+Inputs!F$80+Inputs!F$71*F26+3000-(Income_Statement!F36*(1-Inputs!F$69)+Capex_Depreciation!F35+Income_Statement!F34+NonGAAP_Recon!F18+Cash_Flow!F12+Inputs!F$75)-Inputs!F$67-Inputs!F$76) | G10: =MAX(0,Capex_Depreciation!G23+Inputs!G$80+Inputs!G$71*G26+3000-(Income_Statement!G36*(1-Inputs!G$69)+Capex_Depreciation!G35+Income_Statement!G34+NonGAAP_Recon!G18+Cash_Flow!G12+Inputs!G$75)-Inputs!G$67-Inputs!G$76) | J10: Sized off OPERATING income rather than net income, so it does not depend on the interest it is used to compute. That keeps the workbook free of circular references while still charging a half-year of interest on the year's own issuance.
A11: Interest expense | C11: =(C7-C9)*Inputs!$B$65+C9*Inputs!$B$64+C10*Inputs!$B$64*0.5 | D11: =(D7-D9)*Inputs!$B$65+D9*Inputs!$B$64+D10*Inputs!$B$64*0.5 | E11: =(E7-E9)*Inputs!$B$65+E9*Inputs!$B$64+E10*Inputs!$B$64*0.5 | F11: =(F7-F9)*Inputs!$B$65+F9*Inputs!$B$64+F10*Inputs!$B$64*0.5 | G11: =(G7-G9)*Inputs!$B$65+G9*Inputs!$B$64+G10*Inputs!$B$64*0.5 | J11: FY2026A $4,599m. New debt raised during a year first bears interest in the following year.
A12: New debt issued (plug) | C12: =MAX(0,Cash_Flow!C33) | D12: =MAX(0,Cash_Flow!D33) | E12: =MAX(0,Cash_Flow!E33) | F12: =MAX(0,Cash_Flow!F33) | G12: =MAX(0,Cash_Flow!G33)
A13: Cumulative new debt, closing | C13: =C9+C12 | D13: =D9+D12 | E13: =E9+E12 | F13: =F9+F12 | G13: =G9+G12
A14: TOTAL DEBT, CLOSING | C14: =C7+C8+C12 | D14: =D7+D8+D12 | E14: =E7+E8+E12 | F14: =F7+F8+F12 | G14: =G7+G8+G12
A15: Cash & marketable securities, closing | C15: =Cash_Flow!C36 | D15: =Cash_Flow!D36 | E15: =Cash_Flow!E36 | F15: =Cash_Flow!F36 | G15: =Cash_Flow!G36
A16: NET DEBT | C16: =C14-C15 | D16: =D14-D15 | E16: =E14-E15 | F16: =F14-F15 | G16: =G14-G15
A17: Interest income | C17: =Inputs!$B$79*Inputs!$B$66 | D17: =Cash_Flow!C36*Inputs!$B$66 | E17: =Cash_Flow!D36*Inputs!$B$66 | F17: =Cash_Flow!E36*Inputs!$B$66 | G17: =Cash_Flow!F36*Inputs!$B$66 | J17: Charged on OPENING cash. This is the second circularity break: interest income on closing cash would depend on the cash flow it helps produce.
A19: SHARE COUNT
A20: Diluted shares, opening (m) | C20: 2914 | D20: =C25 | E20: =D25 | F20: =E25 | G20: =F25 | J20: FY2026A diluted weighted-average, 10-K EPS note (R91). NOT the cover-page count of 2,880.471m.
A21: Net dilution from stock awards | C21: =C20*Inputs!$B$72 | D21: =D20*Inputs!$B$72 | E21: =E20*Inputs!$B$72 | F21: =F20*Inputs!$B$72 | G21: =G20*Inputs!$B$72 | J21: DISCLOSED: 10-K MD&A — cumulative potential dilution since 6/1/2023 has run at 1.0% p.a.
A22: Shares issued under the $20bn ATM | C22: =Inputs!C$67/MAX(1,Inputs!C$68)*0.5 | D22: =Inputs!D$67/MAX(1,Inputs!D$68)*1 | E22: =Inputs!E$67/MAX(1,Inputs!E$68)*1 | F22: =Inputs!F$67/MAX(1,Inputs!F$68)*1 | G22: =Inputs!G$67/MAX(1,Inputs!G$68)*1 | J22: DISCLOSED: $20bn ATM entered 2/2/2026, ZERO drawn at 5/31/26 (10-K R70). At $151.94 a full $20bn draw is ~132m shares — four times the mandatory convertible. THIS, not the preferred, is the share-count story.
A23: Mandatory convertible conversion | C23: 0 | D23: 0 | E23: =Inputs!$B$73*4.5/12 | F23: =Inputs!$B$73 | G23: =Inputs!$B$73 | J23: DISCLOSED: converts 1/15/2029 (10-K Note 10) — 4.5 of FY29's 12 months. At $151.94, below the $160.06 lower conversion price, the MAXIMUM ratio of 624.7657 applies: 31.2m shares.
A24: Buybacks | C24: 0 | D24: 0 | E24: 0 | F24: 0 | G24: 0 | J24: FY2026A repurchases were $95m — 0.4m shares. Buybacks have effectively stopped; $6.3bn of authorisation remains unused (10-K R70).
A25: DILUTED SHARES, CLOSING (m) | C25: =C20+C21+C22+C23-C24 | D25: =D20+D21+D22+D23-D24 | E25: =E20+E21+E22+E23-E24 | F25: =F20+F21+F22+F23-F24 | G25: =G20+G21+G22+G23-G24
A26: Basic shares (memo) | C26: =C25-55 | D26: =D25-55 | E26: =E25-55 | F26: =F25-55 | G26: =G25-55 | J26: FY26A gap between basic (2,860m) and diluted (2,914m) was 54m.
A27: Preferred dividends | C27: =Inputs!$B$74 | D27: =Inputs!$B$74 | E27: =Inputs!$B$74*7.5/12 | F27: 0 | G27: 0 | J27: 6.50% on $5.0bn face = $325m p.a., ceasing on conversion.

Sheet Valuation_RPO_NPV
A1: PRIMARY VALUATION — contract-level NPV of the $638bn backlog
A2: No renewal assumed. This isolates what the CONTRACTED book is worth, so the residual against the share price is the part that requires business not yet signed.
A4: $ millions | C4: FY2027E | D4: FY2028E | E4: FY2029E | F4: FY2030E | G4: FY2031E | H4: FY2032E | I4: FY2033E | J4: FY2034E | K4: FY2035E | L4: FY2036E
A6: ASSUMPTIONS — these do NOT switch with the Inputs scenario selector; set them from the reference table below
A7: Backlog EBITDA margin | C7: 0.36 | D7: 0.42 | E7: 0.46 | F7: 0.49 | G7: 0.51 | H7: 0.52 | I7: 0.52 | J7: 0.52 | K7: 0.52 | L7: 0.52 | N7: KEY LEVER. Oracle does not disclose OCI-level cost structure, so this is an analyst construct.
A8: Effective asset turn | C8: 0.36 | N8: KEY LEVER.
A9: Capacity funded by customers | C9: 0.22
A10: Maintenance capex, % of depreciation | C10: 0.35
A11: Cash tax rate on backlog EBIT | C11: 0.19
A12: Residual recovery on remaining NBV | C12: 0.75
A13: Shape of the "thereafter" 20% | H13: 0.3 | I13: 0.25 | J13: 0.2 | K13: 0.15 | L13: 0.1
A14: WACC | C14: =Inputs!$B$82
A15: Equipment / building / land mix, lives | C15: =Inputs!$B$52 | D15: =Inputs!$B$53 | E15: =Inputs!$B$55 | F15: =Inputs!$B$56
A17: BACKLOG CASH FLOWS
A18: Backlog revenue | C18: =RPO_Schedule!C24 | D18: =RPO_Schedule!D24 | E18: =RPO_Schedule!E24 | F18: =RPO_Schedule!F24 | G18: =RPO_Schedule!G24 | H18: =RPO_Schedule!$B$11*(1-RPO_Schedule!$B$16)*H$13 | I18: =RPO_Schedule!$B$11*(1-RPO_Schedule!$B$16)*I$13 | J18: =RPO_Schedule!$B$11*(1-RPO_Schedule!$B$16)*J$13 | K18: =RPO_Schedule!$B$11*(1-RPO_Schedule!$B$16)*K$13 | L18: =RPO_Schedule!$B$11*(1-RPO_Schedule!$B$16)*L$13
A19: Contracted (pre-haircut) revenue | C19: =C18/(1-RPO_Schedule!$B$16) | D19: =D18/(1-RPO_Schedule!$B$16) | E19: =E18/(1-RPO_Schedule!$B$16) | F19: =F18/(1-RPO_Schedule!$B$16) | G19: =G18/(1-RPO_Schedule!$B$16) | H19: =H18/(1-RPO_Schedule!$B$16) | I19: =I18/(1-RPO_Schedule!$B$16) | J19: =J18/(1-RPO_Schedule!$B$16) | ... L19: =L18/(1-RPO_Schedule!$B$16) | N19: Capacity is built to the CONTRACTED schedule. A counterparty failure happens AFTER the capex is sunk — haircutting capex alongside revenue would assume Oracle sees the default coming, and would make counterparty risk look value-accretive.
A20: Prior-year contracted revenue | C20: =$C$19*0.72 | D20: =MAX(C19,C20) | E20: =MAX(D19,D20) | F20: =MAX(E19,E20) | G20: =MAX(F19,F20) | H20: =MAX(G19,G20) | I20: =MAX(H19,H20) | J20: =MAX(I19,I20) | K20: =MAX(J19,J20) | L20: =MAX(K19,K20) | N20: FY26 backlog-served revenue, estimated at 72% of the FY27 figure.
A21: Growth capex (Oracle-funded) | C21: =MAX(0,C19-C20)/$C$8*(1-$C$9) | D21: =MAX(0,D19-D20)/$C$8*(1-$C$9) | E21: =MAX(0,E19-E20)/$C$8*(1-$C$9) | F21: =MAX(0,F19-F20)/$C$8*(1-$C$9) | G21: =MAX(0,G19-G20)/$C$8*(1-$C$9) | H21: =MAX(0,H19-H20)/$C$8*(1-$C$9) | I21: =MAX(0,I19-I20)/$C$8*(1-$C$9) | J21: =MAX(0,J19-J20)/$C$8*(1-$C$9) | ... L21: =MAX(0,L19-L20)/$C$8*(1-$C$9)
A22: Depreciation on backlog assets | C22: =C$21*($C$15/$E$15+$D$15/$F$15)*0.5 | D22: =C$21*($C$15/$E$15+$D$15/$F$15)*1+C$24*($C$15/$E$15+$D$15/$F$15)+D$21*($C$15/$E$15+$D$15/$F$15)*0.5 | E22: =C$21*($C$15/$E$15+$D$15/$F$15)*1+C$24*($C$15/$E$15+$D$15/$F$15)+D$21*($C$15/$E$15+$D$15/$F$15)*1+D$24*($C$15/$E$15+$D$15/$F$15)+E$21*($C$15/$E$15+$D$15/$F$15)*0.5 | F22: =C$21*($C$15/$E$15+$D$15/$F$15)*1+C$24*($C$15/$E$15+$D$15/$F$15)+D$21*($C$15/$E$15+$D$15/$F$15)*1+D$24*($C$15/$E$15+$D$15/$F$15)+E$21*($C$15/$E$15+$D$15/$F$15)*1+E$24*($C$15/$E$15+$D$15/$F$15)+F$21*($C$15/$E$15+$D$15/$F$15)*0.5 | G22: =C$21*($C$15/$E$15+$D$15/$F$15)*1+C$24*($C$15/$E$15+$D$15/$F$15)+D$21*($C$15/$E$15+$D$15/$F$15)*1+D$24*($C$15/$E$15+$D$15/$F$15)+E$21*($C$15/$E$15+$D$15/$F$15)*1+E$24*($C$15/$E$15+$D$15/$F$15)+F$21*($C$15/$E$15+$D$15/$F$15)*1+F$24*($C$15/$E$15+$D$15/$F$15)+G$21*($C$15/$E$15+$D$15/$F$15)*0.5 | H22: =C$21*($C$15/$E$15+$D$15/$F$15)*1+C$24*($C$15/$E$15+$D$15/$F$15)+D$21*($C$15/$E$15+$D$15/$F$15)*1+D$24*($C$15/$E$15+$D$15/$F$15)+E$21*($C$15/$E$15+$D$15/$F$15)*1+E$24*($C$15/$E$15+$D$15/$F$15)+F$21*($C$15/$E$15+$D$15/$F$15)*1+F$24*($C$15/$E$15+$D$15/$F$15)+G$21*($C$15/$E$15+$D$15/$F$15)*1+G$24*($C$15/$E$15+$D$15/$F$15)+H$21*($C$15/$E$15+$D$15/$F$15)*0.5 | I22: =C$21*($C$15/$E$15+$D$15/$F$15)*1+C$24*($C$15/$E$15+$D$15/$F$15)+D$21*($C$15/$E$15+$D$15/$F$15)*1+D$24*($C$15/$E$15+$D$15/$F$15)+E$21*($C$15/$E$15+$D$15/$F$15)*1+E$24*($C$15/$E$15+$D$15/$F$15)+F$21*($C$15/$E$15+$D$15/$F$15)*1+F$24*($C$15/$E$15+$D$15/$F$15)+G$21*($C$15/$E$15+$D$15/$F$15)*1+G$24*($C$15/$E$15+$D$15/$F$15)+H$21*($C$15/$E$15+$D$15/$F$15)*1+H$24*($C$15/$E$15+$D$15/$F$15)+I$21*($C$15/$E$15+$D$15/$F$15)*0.5 | J22: =C$21*($C$15/$E$15+$D$15/$F$15)*1+C$24*($C$15/$E$15+$D$15/$F$15)+D$21*($C$15/$E$15+$D$15/$F$15)*1+D$24*($C$15/$E$15+$D$15/$F$15)+E$21*($C$15/$E$15+$D$15/$F$15)*1+E$24*($C$15/$E$15+$D$15/$F$15)+F$21*($C$15/$E$15+$D$15/$F$15)*1+F$24*($C$15/$E$15+$D$15/$F$15)+G$21*($C$15/$E$15+$D$15/$F$15)*1+G$24*($C$15/$E$15+$D$15/$F$15)+H$21*($C$15/$E$15+$D$15/$F$15)*1+H$24*($C$15/$E$15+$D$15/$F$15)+I$21*($C$15/$E$15+$D$15/$F$15)*1+I$24*($C$15/$E$15+$D$15/$F$15)+J$21*($C$15/$E$15+$D$15/$F$15)*0.5 | K22: =C$21*($C$15/$E$15+$D$15/$F$15)*1+C$24*($C$15/$E$15+$D$15/$F$15)+D$21*($C$15/$E$15+$D$15/$F$15)*1+D$24*($C$15/$E$15+$D$15/$F$15)+E$21*($C$15/$E$15+$D$15/$F$15)*1+E$24*($C$15/$E$15+$D$15/$F$15)+F$21*($C$15/$E$15+$D$15/$F$15)*1+F$24*($C$15/$E$15+$D$15/$F$15)+G$21*($C$15/$E$15+$D$15/$F$15)*1+G$24*($C$15/$E$15+$D$15/$F$15)+H$21*($C$15/$E$15+$D$15/$F$15)*1+H$24*($C$15/$E$15+$D$15/$F$15)+I$21*($C$15/$E$15+$D$15/$F$15)*1+I$24*($C$15/$E$15+$D$15/$F$15)+J$21*($C$15/$E$15+$D$15/$F$15)*1+J$24*($C$15/$E$15+$D$15/$F$15)+K$21*($C$15/$E$15+$D$15/$F$15)*0.5 | L22: =C$21*($C$15/$E$15+$D$15/$F$15)*1+C$24*($C$15/$E$15+$D$15/$F$15)+D$21*($C$15/$E$15+$D$15/$F$15)*1+D$24*($C$15/$E$15+$D$15/$F$15)+E$21*($C$15/$E$15+$D$15/$F$15)*1+E$24*($C$15/$E$15+$D$15/$F$15)+F$21*($C$15/$E$15+$D$15/$F$15)*1+F$24*($C$15/$E$15+$D$15/$F$15)+G$21*($C$15/$E$15+$D$15/$F$15)*1+G$24*($C$15/$E$15+$D$15/$F$15)+H$21*($C$15/$E$15+$D$15/$F$15)*1+H$24*($C$15/$E$15+$D$15/$F$15)+I$21*($C$15/$E$15+$D$15/$F$15)*1+I$24*($C$15/$E$15+$D$15/$F$15)+J$21*($C$15/$E$15+$D$15/$F$15)*1+J$24*($C$15/$E$15+$D$15/$F$15)+K$21*($C$15/$E$15+$D$15/$F$15)*1+K$24*($C$15/$E$15+$D$15/$F$15)+L$21*($C$15/$E$15+$D$15/$F$15)*0.5 | N22: Growth capex depreciates from the year it is spent (half-year convention); maintenance capex enters one year later. The lag is what keeps this non-circular — maintenance capex is itself a function of depreciation.
A23: memo: annual depreciation rate on a $1 vintage | C23: =$C$15/$E$15+$D$15/$F$15
A24: Maintenance capex | C24: =C22*$C$10*C18/MAX($C$18:$L$18) | D24: =D22*$C$10*D18/MAX($C$18:$L$18) | E24: =E22*$C$10*E18/MAX($C$18:$L$18) | F24: =F22*$C$10*F18/MAX($C$18:$L$18) | G24: =G22*$C$10*G18/MAX($C$18:$L$18) | H24: =H22*$C$10*H18/MAX($C$18:$L$18) | I24: =I22*$C$10*I18/MAX($C$18:$L$18) | J24: =J22*$C$10*J18/MAX($C$18:$L$18) | ... L24: =L22*$C$10*L18/MAX($C$18:$L$18)
A25: TOTAL CAPEX | C25: =C21+C24 | D25: =D21+D24 | E25: =E21+E24 | F25: =F21+F24 | G25: =G21+G24 | H25: =H21+H24 | I25: =I21+I24 | J25: =J21+J24 | ... L25: =L21+L24
A26: EBITDA | C26: =C18*C7 | D26: =D18*D7 | E26: =E18*E7 | F26: =F18*F7 | G26: =G18*G7 | H26: =H18*H7 | I26: =I18*I7 | J26: =J18*J7 | ... L26: =L18*L7
A27: EBIT | C27: =C26-C22 | D27: =D26-D22 | E27: =E26-E22 | F27: =F26-F22 | G27: =G26-G22 | H27: =H26-H22 | I27: =I26-I22 | J27: =J26-J22 | ... L27: =L26-L22
A28: Cash tax | C28: =-MAX(0,C27)*$C$11 | D28: =-MAX(0,D27)*$C$11 | E28: =-MAX(0,E27)*$C$11 | F28: =-MAX(0,F27)*$C$11 | G28: =-MAX(0,G27)*$C$11 | H28: =-MAX(0,H27)*$C$11 | I28: =-MAX(0,I27)*$C$11 | J28: =-MAX(0,J27)*$C$11 | ... L28: =-MAX(0,L27)*$C$11
A29: FREE CASH FLOW | C29: =C26+C28-C25 | D29: =D26+D28-D25 | E29: =E26+E28-E25 | F29: =F26+F28-F25 | G29: =G26+G28-G25 | H29: =H26+H28-H25 | I29: =I26+I28-I25 | J29: =J26+J28-J25 | ... L29: =L26+L28-L25
A30: Discount factor | C30: =1/(1+$C$14)^0.5 | D30: =1/(1+$C$14)^1.5 | E30: =1/(1+$C$14)^2.5 | F30: =1/(1+$C$14)^3.5 | G30: =1/(1+$C$14)^4.5 | H30: =1/(1+$C$14)^5.5 | I30: =1/(1+$C$14)^6.5 | J30: =1/(1+$C$14)^7.5 | K30: =1/(1+$C$14)^8.5 | L30: =1/(1+$C$14)^9.5
A31: PV of free cash flow | C31: =C29*C30 | D31: =D29*D30 | E31: =E29*E30 | F31: =F29*F30 | G31: =G29*G30 | H31: =H29*H30 | I31: =I29*I30 | J31: =J29*J30 | ... L31: =L29*L30
A33: BRIDGE TO EQUITY VALUE
A34: PV of backlog cash flows | C34: =SUM($C$31:$L$31)
A35: Gross backlog capex | C35: =SUM($C$25:$L$25)
A36: Accumulated depreciation on it | C36: =SUM($C$22:$L$22)
A37: Remaining net book value at FY2036 | C37: =MAX(0,C35-C36) | N37: Land and the long-lived shell survive the 10-year horizon; the servers do not.
A38: PV of residual asset value | C38: =C37*$C$12/(1+$C$14)^10
A39: BACKLOG ENTERPRISE VALUE | C39: =C34+C38
A41: LEGACY (NON-BACKLOG) BUSINESS — software support, licence, SaaS, services, hardware
A42: Steady-state revenue | C42: 51000 | N42: Software support alone has been a flat $19.5–19.8bn annuity for three years (10-K R89).
A43: EBITDA margin | C43: 0.44
A44: Terminal growth | C44: 0.015
A45: Capex, % of revenue | C45: 0.03
...

Sheet Valuation_DCF
A1: CROSS-CHECK — unlevered FCF DCF and FCFE
A2: On five years of deeply negative free cash flow a growth-perpetuity DCF is mostly terminal assumption. The terminal share of EV is printed below so the reader can see exactly how much.
A4: WACC BUILD
A5: Risk-free rate (10y UST, ^TNX 8/27/26) | C5: 0.04672
A6: Equity risk premium | C6: 0.05 | O6: Analyst input. Mature-market ERP.
A7: Beta, 5-year (source) | C7: 1.72 | O7: stockanalysis.com. Reflects the AI-era repricing of the stock.
A8: Beta, normalised | C8: 1.28 | O8: Analyst estimate: pre-AI / software-peer level.
A9: Beta used | C9: =AVERAGE(C7,C8) | O9: The midpoint is a judgement call, and it is the single largest driver of the answer.
A10: Cost of equity | C10: =C5+C9*C6
A11: Pre-tax cost of NEW debt | C11: =Inputs!$B$64 | O11: Oracle's Feb-2026 30-year priced 6.70%, 40-year 6.85% (10-K MD&A).
A12: Marginal tax rate | C12: 0.2
A13: Market value of equity ($m) | C13: 437660 | O13: 2,880.471m shares (10-K cover) x $151.94.
A14: Market value of debt incl. leases ($m) | C14: 167430 | O14: Single-source figure, 8/27/26. Includes capitalised operating and finance leases.
A15: WACC | C15: =C13/(C13+C14)*C10+C14/(C13+C14)*C11*(1-C12) | O15: At beta 1.72 this is 11.09%; at beta 1.28, 9.51%.
A17: UNLEVERED FREE CASH FLOW
C18: FY2027E | D18: FY2028E | E18: FY2029E | F18: FY2030E | G18: FY2031E
A19: GAAP operating income | C19: =Income_Statement!C35 | D19: =Income_Statement!D35 | E19: =Income_Statement!E35 | F19: =Income_Statement!F35 | G19: =Income_Statement!G35
A20: NOPAT | C20: =C19*(1-Inputs!C$69) | D20: =D19*(1-Inputs!D$69) | E20: =E19*(1-Inputs!E$69) | F20: =F19*(1-Inputs!F$69) | G20: =G19*(1-Inputs!G$69)
A21: + Depreciation & amortisation | C21: =Capex_Depreciation!C35+Income_Statement!C33 | D21: =Capex_Depreciation!D35+Income_Statement!D33 | E21: =Capex_Depreciation!E35+Income_Statement!E33 | F21: =Capex_Depreciation!F35+Income_Statement!F33 | G21: =Capex_Depreciation!G35+Income_Statement!G33
A22: - Capital expenditure | C22: =-Capex_Depreciation!C23 | D22: =-Capex_Depreciation!D23 | E22: =-Capex_Depreciation!E23 | F22: =-Capex_Depreciation!F23 | G22: =-Capex_Depreciation!G23
A23: - Increase in net working capital | C23: =Cash_Flow!C12 | D23: =Cash_Flow!D12 | E23: =Cash_Flow!E12 | F23: =Cash_Flow!F12 | G23: =Cash_Flow!G12
A24: + Customer prepayments | C24: =Cash_Flow!C13 | D24: =Cash_Flow!D13 | E24: =Cash_Flow!E13 | F24: =Cash_Flow!F13 | G24: =Cash_Flow!G13
A25: UNLEVERED FREE CASH FLOW | C25: =SUM(C20:C24) | D25: =SUM(D20:D24) | E25: =SUM(E20:E24) | F25: =SUM(F20:F24) | G25: =SUM(G20:G24)
A26: Discount period (mid-year) | C26: 0.5 | D26: 1.5 | E26: 2.5 | F26: 3.5 | G26: 4.5
A27: Discount factor | C27: =1/(1+$C$15)^C26 | D27: =1/(1+$C$15)^D26 | E27: =1/(1+$C$15)^E26 | F27: =1/(1+$C$15)^F26 | G27: =1/(1+$C$15)^G26
A28: PV of UFCF | C28: =C25*C27 | D28: =D25*D27 | E28: =E25*E27 | F28: =F25*F27 | G28: =G25*G27
A30: TERMINAL VALUE AND EQUITY BRIDGE
A31: Terminal growth | C31: =Inputs!$B$83
A32: Terminal value at FY2031 | C32: =G25*(1+C31)/($C$15-C31)
A33: PV of terminal value | C33: =C32/(1+$C$15)^5
A34: PV of the explicit forecast | C34: =SUM($C$28:$G$28)
A35: ENTERPRISE VALUE | C35: =C34+C33
A36: Terminal value as % of EV | C36: =C33/C35 | O36: Above ~75% the DCF is an opinion about 2032+ dressed as arithmetic. That is exactly why the RPO contract NPV is the primary method here.
